<mujoco model="touchtest">
  <compiler autolimits="true"/>

  <extension>
    <plugin plugin="mujoco.sensor.touch_grid"/>
  </extension>

  <asset>
    <texture name="grid" type="2d" builtin="checker" rgb1=".1 .2 .3" rgb2=".2 .3 .4" width="300" height="300" mark="edge" markrgb=".2 .3 .4"/>
    <material name="grid" texture="grid" texrepeat="3 1" texuniform="true"/>
    <!-- Replaced hfield with STL mesh -->
    <mesh name="a_mesh" file="a.stl" scale="0.2 0.2 0.02"/>
    <mesh name="digit_mesh" file="../tacto_examples/meshes/digit.STL" scale="1 1 1"/>
  </asset>

  <visual>
      <headlight ambient=".7 .7 .7" diffuse=".2 .2 .2" specular="0.1 0.1 0.1"/>
      <map znear="0.01"/>
      <scale contactwidth=".02" contactheight=".5"/>
  </visual>

  <default>
    <geom friction="0.4" solimp="0 0.95 0.02"/>
  </default>

  <statistic center="0 0 1" extent="1" meansize=".1"/>

  <worldbody>
    <light pos="1 0 .3" dir="-1 0 -.3"/>
    <light pos="-1 0 .3" dir="1 0 -.3"/>
    <geom name="floor" pos="0 0 -0.01" type="plane" size="1 1 .01"/>

    <!-- Replaced hfield geom with STL mesh geom -->
    <body name="a">
      <geom name="a" type="mesh" mesh="a_mesh" pos="0 0 0" rgba=".5 .5 .7 0.2"/>
      <geom name="dummy" type="sphere" size="0.05" pos="0.1 0.1 0.1" rgba="1 0 0 1"/>
    </body>

    <body name="digit" pos="0 0 1" quat="0.707 0 0.707 0">
      <inertial pos="0 0 0" mass="0.1" diaginertia="1 1 1"/>
      <geom type="mesh" mesh="digit_mesh" rgba="1 1 1 0.2" contype="0" conaffinity="0"/>
      <geom type="mesh" mesh="digit_mesh" rgba="0 0 0 0"/>
      <site name="touch" pos="0 0 0.015" quat="0.5 0.5 -0.5 -0.5"/>
      <joint name="x" type="slide" axis="1 0 0" damping="1"/>
      <joint name="y" type="slide" axis="0 1 0" damping="1"/>
      <joint name="z" type="slide" axis="0 0 1" damping="1"/>
      <joint name="rx" type="hinge" axis="1 0 0" damping="0.5" springref="0" stiffness="1"/>
      <joint name="ry" type="hinge" axis="0 1 0" damping="0.5" springref="0" stiffness="1"/>
      <joint name="rz" type="hinge" axis="0 0 1" damping="0.5" springref="0" stiffness="1"/>
    </body>
  </worldbody>

  <sensor>
    <plugin name="touch" plugin="mujoco.sensor.touch_grid" objtype="site" objname="touch">
      <config key="size" value="120 160"/>
      <config key="fov" value="60 70"/>
      <config key="gamma" value="0"/>
      <config key="nchannel" value="3"/>
    </plugin>
  </sensor>
</mujoco>